Workbook
Name EngMaths: '[1]Table 19 data'!$A$205:$A$206
Name EngMaths: 'Table 19 data'!$A$205:$A$206
Name Gender: '[1]Table 16 data'!$B$170:$B$172
Name Gender: 'Table 16 data'!$B$170:$B$172
Name qa: '[2]Table 16 data'!$B$3:$AI$167
Name T16Percentage: '[1]Table 16 data'!$B$3:$AI$167
Name T16Percentage: 'Table 16 data'!$B$3:$AI$167
Name Table17dropdown: '[1]Table 16 data'!$B$175:$B$176
Name Table17dropdown: 'Table 16 data'!$B$175:$B$176

Sheet Index
A1: GCSE AND EQUIVALENT RESULTS IN ENGLAND 2012/13 (REVISED)
A3: Index of tables
A5: National tables
A6: Table 7 | B6: GCSE entries and achievements in selected subjects of pupils at the end of key stage 4 in schools (number)
A7: Table 8 | B7: GCSE entries and achievements in selected subjects of pupils at the end of key stage 4 in schools (percentage of pupils entering the subject)
A8: Table 9 | B8: GCSE entries and achievements in selected subjects of pupils at the end of key stage 4 in schools (percentage of all pupils)
A9: Table 10a | B9: GCSE entries in selected subjects by pupils at the end of key stage 4 by school type (percentage)
A10: Table 10b | B10: GCSE entries in selected subjects by pupils at the end of key stage 4 by admissions basis (percentage)
A11: Table 11 | B11: GCSE results of pupils at the end of key stage 4 in schools, by subject and grade
A12: Table 12 | B12: International GCSE, Cambridge International Certificate and Edexcel Level1/2 Certificate results of pupils at the end of key stage 4 in schools, by subject and grade
A13: Table 13 | B13: Results of GCSEs in Applied subjects of pupils at the end of key stage 4 in schools, by subject and grade
A14: Table 14 | B14: GCSE (Short Course) results of pupils at the end of key stage 4 in all schools, by subject and grade
A15: Table 15 | B15: Other Qualification results of pupils at the end of key stage 4 in all schools, by type of qualification
A17: Local Authority tables
A18: Table 16 | B18: GCSE and equivalent results of pupils at the end of key stage 4 by gender for each local authority and region
A19: Table 17 | B19: GCSE and equivalent results of pupils at the end of key stage 4 for each local authority and region, 2005/06 to 2012/13
A20: Table 18 | B20: The English Baccalaureate by local authority and region
A21: Table 19 | B21: Percentage of pupils in state-funded mainstream schools making expected progress in English and mathematics between key stage 2 and key stage 4, by local authority and region, 2008/09 to 2012/13
A22: Table 20 | B22: Percentage of pupils in state-funded schools making expected progress in English and mathematics between key stage 2 and key stage 4, by local authority and region, 2008/09 to 2012/13
A23: Table 21 | B23: Number of schools below the floor standard by local authority and region

Sheet Table 7
A1: Table 7: GCSE entries and achievements1 in selected subjects of pupils at the end of key stage 4 in schools (number)
A2: Year: 2012/132 (Revised)
A3: Coverage: England
L4: Pupils (thousands)
B5: Entered GCSE | F5: Achieved grades A*-C | J5: Achieved grades A*-G
B6: Boys | C6: Girls | D6: Total | F6: Boys | G6: Girls | H6: Total | J6: Boys | K6: Girls | L6: Total
A8: Any Subject | B8: 314.8 | C8: 304.9 | D8: 619.6 | F8: 257.3 | G8: 268.2 | H8: 525.5 | J8: 311.9 | K8: 303.1 | L8: 615
A10: English & Mathematics | B10: 269.1 | C10: 270.3 | D10: 539.3 | F10: 158.3 | G10: 185.8 | H10: 344.1 | J10: 264.3 | K10: 266.2 | L10: 530.5
A11: Mathematics & Science | B11: 232.6 | C11: 234.2 | D11: 466.9 | F11: 159.5 | G11: 168.7 | H11: 328.2 | J11: 229.3 | K11: 231.4 | L11: 460.7
A12: English, Mathematics & Science | B12: 215.6 | C12: 221.7 | D12: 437.4 | F12: 133.5 | G12: 156.5 | H12: 290 | J12: 212.8 | K12: 219.4 | L12: 432.1
A14: English3 | B14: 274.7 | C14: 276.1 | D14: 550.8 | F14: 174.1 | G14: 215.3 | H14: 389.3 | J14: 272.6 | K14: 274.9 | L14: 547.5
A15: English | B15: 86.9 | C15: 59.7 | D15: 146.6 | F15: 28.6 | G15: 26.7 | H15: 55.3 | J15: 85.3 | K15: 58.9 | L15: 144.2
A16: English Language4 | B16: 187.8 | C16: 216.4 | D16: 404.2 | F16: 145.5 | G16: 188.6 | H16: 334.1 | J16: 187.3 | K16: 216 | L16: 403.3
A18: Mathematics | B18: 297.3 | C18: 290.5 | D18: 587.8 | F18: 214.9 | G18: 212.6 | H18: 427.5 | J18: 291.5 | K18: 285.5 | L18: 577.1
A20: Any Science | B20: 239.4 | C20: 240.9 | D20: 480.3 | F20: 170.5 | G20: 181.9 | H20: 352.4 | J20: 236.9 | K20: 238.8 | L20: 475.7
A21: Core Science | B21: 158.4 | C21: 163.6 | D21: 322 | F21: 89.8 | G21: 103.8 | H21: 193.5 | J21: 155.8 | K21: 161.5 | L21: 317.2
A22: Additional Science | B22: 119.6 | C22: 128.9 | D22: 248.5 | F22: 74 | G22: 88.1 | H22: 162.1 | J22: 118.4 | K22: 128 | L22: 246.4
A23: Additional Applied Science | B23: 5.7 | C23: 6.1 | D23: 11.8 | F23: 1.5 | G23: 2.4 | H23: 3.9 | J23: 5.5 | K23: 6 | L23: 11.5
... A66: Applied Art and Design | B66: 0.4 | C66: 0.7 | D66: 1.1 | F66: 0.2 | G66: 0.5 | H66: 0.8 | J66: 0.4 | K66: 0.7 | L66: 1
A67: Applied Physical Education | B67: . | C67: . | D67: . | F67: . | G67: . | H67: . | J67: . | K67: . | L67: .
A68: Art and Design | B68: 52.2 | C68: 104.2 | D68: 156.5 | F68: 33.9 | G68: 86.7 | H68: 120.5 | J68: 51.4 | K68: 103.6 | L68: 155
A69: Communication Studies | B69: 4.1 | C69: 4.9 | D69: 9 | F69: 2 | G69: 3.5 | H69: 5.5 | J69: 4 | K69: 4.9 | L69: 8.8
A70: Construction | B70: 0 | C70: 0 | D70: 0 | F70: 0 | G70: 0 | H70: 0 | J70: 0 | K70: 0 | L70: 0
A71: Drama | B71: 27.1 | C71: 42.6 | D71: 69.8 | F71: 17.9 | G71: 33.1 | H71: 51 | J71: 26.9 | K71: 42.4 | L71: 69.2
A72: English Literature | B72: 197.8 | C72: 224 | D72: 421.8 | F72: 140.5 | G72: 186.9 | H72: 327.5 | J72: 195.6 | K72: 222.6 | L72: 418.2
A73: English Studies | B73: 1.1 | C73: 1 | D73: 2.1 | F73: 0.4 | G73: 0.5 | H73: 0.9 | J73: 1.1 | K73: 1 | L73: 2.1
A74: General Studies | B74: 2.5 | C74: 2.4 | D74: 4.9 | F74: 1 | G74: 1.3 | H74: 2.2 | J74: 2.2 | K74: 2.3 | L74: 4.5
A75: Health and Social Care | B75: 0.4 | C75: 7.4 | D75: 7.8 | F75: 0.1 | G75: 4 | H75: 4.2 | J75: 0.4 | K75: 7.2 | L75: 7.5
A76: Hospitality and Catering | B76: 0.7 | C76: 1.3 | D76: 2 | F76: 0.3 | G76: 0.9 | H76: 1.2 | J76: 0.7 | K76: 1.3 | L76: 2
A77: Leisure and Tourism | B77: 1.1 | C77: 1.4 | D77: 2.5 | F77: 0.3 | G77: 0.7 | H77: 1 | J77: 1 | K77: 1.3 | L77: 2.4
A78: Manufacturing | B78: 0.1 | C78: 0 | D78: 0.1 | F78: 0 | G78: 0 | H78: 0 | J78: 0.1 | K78: 0 | L78: 0.1
A79: Media/Film/TV | B79: 24.1 | C79: 24.6 | D79: 48.7 | F79: 13.5 | G79: 18.6 | H79: 32.1 | J79: 23.6 | K79: 24.3 | L79: 48
A80: Media: Communication and Production | B80: . | C80: . | D80: . | F80: . | G80: . | H80: . | J80: . | K80: . | L80: .
A81: Music | B81: 20.7 | C81: 20.6 | D81: 41.3 | F81: 15.3 | G81: 16.3 | H81: 31.6 | J81: 20.4 | K81: 20.4 | L81: 40.8
A82: Performing Arts | B82: 0.9 | C82: 2.1 | D82: 3.1 | F82: 0.4 | G82: 1.4 | H82: 1.9 | J82: 0.9 | K82: 2.1 | L82: 3
A83: Physical Education | B83: 60.9 | C83: 40.7 | D83: 101.6 | F83: 43 | G83: 29 | H83: 72 | J83: 60.8 | K83: 40.5 | L83: 101.3
A84: Religious Studies | B84: 104.9 | C84: 124.1 | D84: 229 | F84: 70.2 | G84: 98.4 | H84: 168.6 | J84: 102.3 | K84: 122.7 | L84: 225
A85: Statistics | B85: 23.2 | C85: 21.2 | D85: 44.5 | F85: 17.5 | G85: 17.1 | H85: 34.6 | J85: 22.7 | K85: 20.8 | L85: 43.5
A86: Vocational Studies | B86: 15.8 | C86: 17.1 | D86: 32.9 | F86: 8.4 | G86: 11.9 | H86: 20.3 | J86: 15.5 | K86: 16.9 | L86: 32.5
L88: Source: 2012/13 key stage 4 attainment data (Revised)
...

Sheet Table 8
A1: Table 8: GCSE entries and achievements1 in selected subjects of pupils at the end of key stage 4 in schools (percentage of pupils entering the subject)
A2: Year: 2012/132 (Revised)
A3: Coverage: England
C4: Thousands | D4: As a percentage of pupils at the end of key stage 4 entering the subject
B5: Entered GCSE | F5: Achieved grades A*-C | J5: Achieved grades A*-G
B6: Boys | C6: Girls | D6: Total | F6: Boys | G6: Girls | H6: Total | J6: Boys | K6: Girls | L6: Total
A8: Any Subject | B8: 314.8 | C8: 304.9 | D8: 619.6 | F8: 82 | G8: 88 | H8: 85 | J8: 99 | K8: 99 | L8: 99
A10: English & Mathematics | B10: 269.1 | C10: 270.3 | D10: 539.3 | F10: 59 | G10: 69 | H10: 64 | J10: 98 | K10: 99 | L10: 98
A11: Mathematics & Science | B11: 232.6 | C11: 234.2 | D11: 466.9 | F11: 69 | G11: 72 | H11: 70 | J11: 99 | K11: 99 | L11: 99
A12: English, Mathematics & Science | B12: 215.6 | C12: 221.7 | D12: 437.4 | F12: 62 | G12: 71 | H12: 66 | J12: 99 | K12: 99 | L12: 99
A14: English3 | B14: 274.7 | C14: 276.1 | D14: 550.8 | F14: 63 | G14: 78 | H14: 71 | J14: 99 | K14: 100 | L14: 99
A15: English | B15: 86.9 | C15: 59.7 | D15: 146.6 | F15: 33 | G15: 45 | H15: 38 | J15: 98 | K15: 99 | L15: 98
A16: English Language4 | B16: 187.8 | C16: 216.4 | D16: 404.2 | F16: 77 | G16: 87 | H16: 83 | J16: 100 | K16: 100 | L16: 100
A18: Mathematics | B18: 297.3 | C18: 290.5 | D18: 587.8 | F18: 72 | G18: 73 | H18: 73 | J18: 98 | K18: 98 | L18: 98
A20: Any Science | B20: 239.4 | C20: 240.9 | D20: 480.3 | F20: 71 | G20: 76 | H20: 73 | J20: 99 | K20: 99 | L20: 99
A21: Core Science | B21: 158.4 | C21: 163.6 | D21: 322 | F21: 57 | G21: 63 | H21: 60 | J21: 98 | K21: 99 | L21: 99
A22: Additional Science | B22: 119.6 | C22: 128.9 | D22: 248.5 | F22: 62 | G22: 68 | H22: 65 | J22: 99 | K22: 99 | L22: 99
A23: Additional Applied Science | B23: 5.7 | C23: 6.1 | D23: 11.8 | F23: 27 | G23: 38 | H23: 33 | J23: 96 | K23: 98 | L23: 97
... A66: Applied Art and Design | B66: 0.4 | C66: 0.7 | D66: 1.1 | F66: 57 | G66: 80 | H66: 71 | J66: 99 | K66: 99 | L66: 99
A67: Applied Physical Education | B67: . | C67: . | D67: . | F67: . | G67: . | H67: . | J67: . | K67: . | L67: .
A68: Art and Design | B68: 52.2 | C68: 104.2 | D68: 156.5 | F68: 65 | G68: 83 | H68: 77 | J68: 98 | K68: 99 | L68: 99
A69: Communication Studies | B69: 4.1 | C69: 4.9 | D69: 9 | F69: 49 | G69: 71 | H69: 61 | J69: 97 | K69: 99 | L69: 98
A70: Construction | B70: 0 | C70: 0 | D70: 0 | F70: 51 | G70: 0 | H70: 51 | J70: 98 | K70: 0 | L70: 98
A71: Drama | B71: 27.1 | C71: 42.6 | D71: 69.8 | F71: 66 | G71: 78 | H71: 73 | J71: 99 | K71: 99 | L71: 99
A72: English Literature | B72: 197.8 | C72: 224 | D72: 421.8 | F72: 71 | G72: 83 | H72: 78 | J72: 99 | K72: 99 | L72: 99
A73: English Studies | B73: 1.1 | C73: 1 | D73: 2.1 | F73: 37 | G73: 51 | H73: 43 | J73: 98 | K73: 99 | L73: 98
A74: General Studies | B74: 2.5 | C74: 2.4 | D74: 4.9 | F74: 38 | G74: 53 | H74: 46 | J74: 89 | K74: 95 | L74: 92
A75: Health and Social Care | B75: 0.4 | C75: 7.4 | D75: 7.8 | F75: 31 | G75: 55 | H75: 54 | J75: 90 | K75: 98 | L75: 97
A76: Hospitality and Catering | B76: 0.7 | C76: 1.3 | D76: 2 | F76: 43 | G76: 66 | H76: 58 | J76: 99 | K76: 100 | L76: 100
A77: Leisure and Tourism | B77: 1.1 | C77: 1.4 | D77: 2.5 | F77: 29 | G77: 52 | H77: 41 | J77: 91 | K77: 96 | L77: 94
A78: Manufacturing | B78: 0.1 | C78: 0 | D78: 0.1 | F78: 31 | G78: 29 | H78: 30 | J78: 98 | K78: 93 | L78: 97
A79: Media/Film/TV | B79: 24.1 | C79: 24.6 | D79: 48.7 | F79: 56 | G79: 76 | H79: 66 | J79: 98 | K79: 99 | L79: 98
A80: Media: Communication and Production | B80: . | C80: . | D80: . | F80: . | G80: . | H80: . | J80: . | K80: . | L80: .
A81: Music | B81: 20.7 | C81: 20.6 | D81: 41.3 | F81: 74 | G81: 79 | H81: 77 | J81: 99 | K81: 99 | L81: 99
A82: Performing Arts | B82: 0.9 | C82: 2.1 | D82: 3.1 | F82: 47 | G82: 67 | H82: 61 | J82: 97 | K82: 99 | L82: 98
A83: Physical Education | B83: 60.9 | C83: 40.7 | D83: 101.6 | F83: 71 | G83: 71 | H83: 71 | J83: 100 | K83: 100 | L83: 100
A84: Religious Studies | B84: 104.9 | C84: 124.1 | D84: 229 | F84: 67 | G84: 79 | H84: 74 | J84: 98 | K84: 99 | L84: 98
A85: Statistics | B85: 23.2 | C85: 21.2 | D85: 44.5 | F85: 75 | G85: 81 | H85: 78 | J85: 98 | K85: 98 | L85: 98
A86: Vocational Studies | B86: 15.8 | C86: 17.1 | D86: 32.9 | F86: 53 | G86: 70 | H86: 62 | J86: 98 | K86: 99 | L86: 99
L88: Source: 2012/13 key stage 4 attainment data (Revised)
...

Sheet Table 9
A1: Table 9: GCSE entries and achievements1 in selected subjects of pupils at the end of key stage 4 in schools (percentage of all pupils)
A2: Year: 2012/132 (Revised)
A3: Coverage: England
F4: As a percentage of pupils at the end of key stage 4 in all schools3
B5: Entered GCSE | F5: Achieved grades A*-C | J5: Achieved grades A*-G
B6: Boys | C6: Girls | D6: Total | F6: Boys | G6: Girls | H6: Total | J6: Boys | K6: Girls | L6: Total
A8: Any Subject (Thousands) | B8: 314.8 | C8: 304.9 | D8: 619.6 | F8: 257.3 | G8: 268.2 | H8: 525.5 | J8: 311.9 | K8: 303.1 | L8: 615
A9: Any Subject | B9: 97 | C9: 99 | D9: 98 | F9: 79 | G9: 87 | H9: 83 | J9: 96 | K9: 98 | L9: 97
A11: English & Mathematics | B11: 83 | C11: 88 | D11: 85 | F11: 49 | G11: 60 | H11: 54 | J11: 82 | K11: 86 | L11: 84
A12: Mathematics & Science | B12: 72 | C12: 76 | D12: 74 | F12: 49 | G12: 55 | H12: 52 | J12: 71 | K12: 75 | L12: 73
A13: English, Mathematics & Science | B13: 67 | C13: 72 | D13: 69 | F13: 41 | G13: 51 | H13: 46 | J13: 66 | K13: 71 | L13: 68
A15: English4 | B15: 85 | C15: 89 | D15: 87 | F15: 54 | G15: 70 | H15: 62 | J15: 84 | K15: 89 | L15: 87
A16: English | B16: 27 | C16: 19 | D16: 23 | F16: 9 | G16: 9 | H16: 9 | J16: 26 | K16: 19 | L16: 23
A17: English Language5 | B17: 58 | C17: 70 | D17: 64 | F17: 45 | G17: 61 | H17: 53 | J17: 58 | K17: 70 | L17: 64
A19: Mathematics | B19: 92 | C19: 94 | D19: 93 | F19: 66 | G19: 69 | H19: 68 | J19: 90 | K19: 92 | L19: 91
A21: Any Science | B21: 74 | C21: 78 | D21: 76 | F21: 53 | G21: 59 | H21: 56 | J21: 73 | K21: 77 | L21: 75
A22: Core Science | B22: 49 | C22: 53 | D22: 51 | F22: 28 | G22: 34 | H22: 31 | J22: 48 | K22: 52 | L22: 50
A23: Additional Science | B23: 37 | C23: 42 | D23: 39 | F23: 23 | G23: 29 | H23: 26 | J23: 37 | K23: 41 | L23: 39
... A67: Applied Art and Design | B67: 0 | C67: 0 | D67: 0 | F67: 0 | G67: 0 | H67: 0 | J67: 0 | K67: 0 | L67: 0
A68: Applied Physical Education | B68: . | C68: . | D68: . | E68: . | F68: . | G68: . | H68: . | I68: . | J68: . | K68: . | L68: .
A69: Art and Design | B69: 16 | C69: 34 | D69: 25 | F69: 10 | G69: 28 | H69: 19 | J69: 16 | K69: 34 | L69: 24
A70: Communication Studies | B70: 1 | C70: 2 | D70: 1 | F70: 1 | G70: 1 | H70: 1 | J70: 1 | K70: 2 | L70: 1
A71: Construction | B71: 0 | C71: 0 | D71: 0 | F71: 0 | G71: 0 | H71: 0 | J71: 0 | K71: 0 | L71: 0
A72: Drama | B72: 8 | C72: 14 | D72: 11 | F72: 6 | G72: 11 | H72: 8 | J72: 8 | K72: 14 | L72: 11
A73: English Literature | B73: 61 | C73: 73 | D73: 67 | F73: 43 | G73: 61 | H73: 52 | J73: 60 | K73: 72 | L73: 66
A74: English Studies | B74: 0 | C74: 0 | D74: 0 | F74: 0 | G74: 0 | H74: 0 | J74: 0 | K74: 0 | L74: 0
A75: General Studies | B75: 1 | C75: 1 | D75: 1 | F75: 0 | G75: 0 | H75: 0 | J75: 1 | K75: 1 | L75: 1
A76: Health and Social Care | B76: 0 | C76: 2 | D76: 1 | F76: 0 | G76: 1 | H76: 1 | J76: 0 | K76: 2 | L76: 1
A77: Hospitality and Catering | B77: 0 | C77: 0 | D77: 0 | F77: 0 | G77: 0 | H77: 0 | J77: 0 | K77: 0 | L77: 0
A78: Leisure and Tourism | B78: 0 | C78: 0 | D78: 0 | F78: 0 | G78: 0 | H78: 0 | J78: 0 | K78: 0 | L78: 0
A79: Manufacturing | B79: 0 | C79: 0 | D79: 0 | F79: 0 | G79: 0 | H79: 0 | J79: 0 | K79: 0 | L79: 0
A80: Media/Film/TV | B80: 7 | C80: 8 | D80: 8 | F80: 4 | G80: 6 | H80: 5 | J80: 7 | K80: 8 | L80: 8
A81: Media: Communication and Production | B81: . | C81: . | D81: . | F81: . | G81: . | H81: . | J81: . | K81: . | L81: .
A82: Music | B82: 6 | C82: 7 | D82: 7 | F82: 5 | G82: 5 | H82: 5 | J82: 6 | K82: 7 | L82: 6
A83: Performing Arts | B83: 0 | C83: 1 | D83: 0 | F83: 0 | G83: 0 | H83: 0 | J83: 0 | K83: 1 | L83: 0
A84: Physical Education | B84: 19 | C84: 13 | D84: 16 | F84: 13 | G84: 9 | H84: 11 | J84: 19 | K84: 13 | L84: 16
A85: Religious Studies | B85: 32 | C85: 40 | D85: 36 | F85: 22 | G85: 32 | H85: 27 | J85: 32 | K85: 40 | L85: 36
A86: Statistics | B86: 7 | C86: 7 | D86: 7 | F86: 5 | G86: 6 | H86: 5 | J86: 7 | K86: 7 | L86: 7
A87: Vocational Studies | B87: 5 | C87: 6 | D87: 5 | F87: 3 | G87: 4 | H87: 3 | J87: 5 | K87: 5 | L87: 5
L89: Source: 2012/13 key stage 4 attainment data (Revised)
...

Sheet Table 10a
A1: Table 10a: GCSE entries in selected subjects by pupils at the end of key stage 4 by school type (percentage)
A2: Year: 2012/131 (Revised)
A3: Coverage: England
Q4: As a percentage of pupils at the end of key stage 4 in each school type2
B5: All state-funded mainstream schools3 | C5: Local authority maintained mainstream schools4 | D5: Academies and free schools5 | E5: Sponsored academies | F5: Converter academies | G5: Free schools, university technical colleges (UTCs) and studio schools | H5: State-funded special schools6 | I5: All state-funded schools7 | J5: Hospital schools and alternative provision including academy and free school alternative provision and pupil referral units | K5: All state-funded schools, hospital schools and alternative provision including academy and free school alternative provision and pupil referral units | L5: Non-maintained special schools | M5: Independent schools | N5: Independent special schools | O5: All independent schools8 | P5: All special schools | Q5: All schools
A7: Any Subject | B7: 100 | C7: 100 | D7: 100 | E7: 99 | F7: 100 | G7: 99 | H7: 34 | I7: 98 | J7: 61 | K7: 98 | L7: 49 | M7: 95 | N7: 50 | O7: 92 | P7: 38 | Q7: 97
A9: English & Mathematics | B9: 92 | C9: 93 | D9: 91 | E9: 85 | F9: 92 | G9: 88 | H9: 13 | I9: 90 | J9: 30 | K9: 89 | L9: 25 | M9: 39 | N9: 28 | O9: 38 | P9: 16 | Q9: 85
A10: Mathematics & Science | B10: 79 | C10: 79 | D10: 79 | E10: 63 | F10: 83 | G10: 80 | H10: 12 | I10: 78 | J10: 25 | K10: 77 | L10: 28 | M10: 38 | N10: 29 | O10: 37 | P10: 16 | Q10: 74
A11: English, Mathematics & Science | B11: 75 | C11: 75 | D11: 74 | E11: 55 | F11: 79 | G11: 75 | H11: 8 | I11: 73 | J11: 17 | K11: 72 | L11: 22 | M11: 32 | N11: 22 | O11: 31 | P11: 11 | Q11: 69
A13: English9 | B13: 93 | C13: 93 | D13: 92 | E13: 86 | F13: 94 | G13: 88 | H13: 15 | I13: 91 | J13: 32 | K13: 90 | L13: 27 | M13: 50 | N13: 33 | O13: 49 | P13: 19 | Q13: 87
A14: English | B14: 25 | C14: 25 | D14: 24 | E14: 40 | F14: 20 | G14: 34 | H14: 14 | I14: 25 | J14: 25 | K14: 25 | L14: 18 | M14: 5 | N14: 26 | O14: 6 | P14: 16 | Q14: 23
A15: English Language10 | B15: 68 | C15: 68 | D15: 67 | E15: 46 | F15: 74 | G15: 54 | H15: 2 | I15: 67 | J15: 6 | K15: 66 | L15: 9 | M15: 45 | N15: 7 | O15: 43 | P15: 3 | Q15: 64
A17: Mathematics | B17: 98 | C17: 98 | D17: 98 | E17: 99 | F17: 98 | G17: 99 | H17: 23 | I17: 97 | J17: 56 | K17: 96 | L17: 38 | M17: 50 | N17: 41 | O17: 50 | P17: 27 | Q17: 93
A19: Any Science | B19: 80 | C19: 80 | D19: 80 | E19: 63 | F19: 84 | G19: 80 | H19: 17 | I19: 79 | J19: 28 | K19: 78 | L19: 32 | M19: 53 | N19: 32 | O19: 52 | P19: 20 | Q19: 76
A20: Core Science | B20: 54 | C20: 56 | D20: 52 | E20: 47 | F20: 53 | G20: 55 | H20: 16 | I20: 53 | J20: 26 | K20: 53 | L20: 29 | M20: 25 | N20: 30 | O20: 25 | P20: 19 | Q20: 51
A21: Additional Science | B21: 42 | C21: 44 | D21: 41 | E21: 33 | F21: 43 | G21: 51 | H21: 1 | I21: 42 | J21: 2 | K21: 41 | L21: 10 | M21: 21 | N21: 7 | O21: 20 | P21: 2 | Q21: 39
A22: Additional Applied Science | B22: 2 | C22: 2 | D22: 2 | E22: 1 | F22: 2 | G22: 0 | H22: 0 | I22: 2 | J22: 1 | K22: 2 | L22: x | M22: 0 | N22: 1 | O22: 0 | P22: 0 | Q22: 2
A23: Physics | B23: 25 | C23: 23 | D23: 26 | E23: 15 | F23: 30 | G23: 23 | H23: 0 | I23: 24 | J23: 0 | K23: 24 | L23: 1 | M23: 23 | N23: 0 | O23: 21 | P23: 0 | Q23: 24
A24: Chemistry | B24: 25 | C24: 23 | D24: 27 | E24: 15 | F24: 30 | G24: 23 | H24: 0 | I24: 24 | J24: 0 | K24: 24 | L24: 1 | M24: 25 | N24: 0 | O24: 23 | P24: 0 | Q24: 24
A25: Biological Sciences | B25: 25 | C25: 23 | D25: 27 | E25: 15 | F25: 30 | G25: 23 | H25: 0 | I25: 25 | J25: 1 | K25: 24 | L25: 1 | M25: 25 | N25: 1 | O25: 24 | P25: 1 | Q25: 24
A26: Other Sciences11 | B26: 1 | C26: 1 | D26: 1 | E26: 1 | F26: 1 | G26: 0 | H26: 0 | I26: 1 | J26: 0 | K26: 1 | L26: 1 | M26: 1 | N26: 0 | O26: 1 | P26: 0 | Q26: 1
A28: Any Design & Technology | B28: 33 | C28: 33 | D28: 33 | E28: 25 | F28: 35 | G28: 15 | H28: 5 | I28: 33 | J28: 2 | K28: 32 | L28: 15 | M28: 19 | N28: 7 | O28: 18 | P28: 5 | Q28: 31
A29: D & T: Electronic Products | B29: 1 | C29: 1 | D29: 2 | E29: 1 | F29: 2 | G29: 0 | H29: 0 | I29: 1 | J29: x | K29: 1 | L29: 0 | M29: 1 | N29: x | O29: 1 | P29: 0 | Q29: 1
A30: D & T: Food Technology | B30: 8 | C30: 8 | D30: 7 | E30: 6 | F30: 8 | G30: x | H30: 1 | I30: 7 | J30: 0 | K30: 7 | L30: 1 | M30: 2 | N30: 1 | O30: 2 | P30: 1 | Q30: 7
A31: D & T: Graphic Products | B31: 6 | C31: 6 | D31: 6 | E31: 4 | F31: 7 | G31: 1 | H31: 0 | I31: 6 | J31: 0 | K31: 6 | L31: 0 | M31: 2 | N31: 0 | O31: 2 | P31: 0 | Q31: 6
A32: D & T: Resistant Materials | B32: 8 | C32: 8 | D32: 8 | E32: 7 | F32: 9 | G32: 3 | H32: 3 | I32: 8 | J32: 1 | K32: 8 | L32: 15 | M32: 10 | N32: 5 | O32: 10 | P32: 4 | Q32: 8
A33: D & T: Systems & Control | B33: 1 | C33: 1 | D33: 1 | E33: 0 | F33: 1 | G33: 0 | H33: 0 | I33: 1 | J33: x | K33: 1 | L33: 0 | M33: 0 | N33: 0 | O33: 0 | P33: 0 | Q33: 1
A34: D & T: Textiles Technology | B34: 5 | C34: 5 | D34: 5 | E34: 3 | F34: 5 | G34: 1 | H34: 0 | I34: 5 | J34: 0 | K34: 5 | L34: 0 | M34: 2 | N34: 0 | O34: 2 | P34: 0 | Q34: 4
A35: Other Design and Technology12 | B35: 6 | C35: 6 | D35: 6 | E35: 6 | F35: 6 | G35: 10 | H35: 0 | I35: 6 | J35: 0 | K35: 6 | L35: 0 | M35: 3 | N35: 1 | O35: 3 | P35: 1 | Q35: 5
A36: Applied Engineering | B36: 0 | C36: 0 | D36: 0 | E36: 0 | F36: 1 | G36: 0 | H36: 0 | I36: 0 | J36: x | K36: 0 | L36: 0 | M36: 0 | N36: 0 | O36: 0 | P36: 0 | Q36: 0
A37: Information Technology13 | B37: 9 | C37: 9 | D37: 10 | E37: 6 | F37: 11 | G37: 27 | H37: 1 | I37: 9 | J37: 2 | K37: 9 | L37: 0 | M37: 10 | N37: 2 | O37: 9 | P37: 1 | Q37: 9
A38: Business Studies | B38: 11 | C38: 9 | D38: 12 | E38: 6 | F38: 14 | G38: 32 | H38: x | I38: 11 | J38: 0 | K38: 10 | L38: x | M38: 9 | N38: 1 | O38: 8 | P38: 0 | Q38: 10
A39: Applied Business | B39: 1 | C39: 1 | D39: 1 | E39: 0 | F39: 1 | G39: 0 | H39: 0 | I39: 1 | J39: 0 | K39: 1 | L39: 0 | M39: 0 | N39: 0 | O39: 0 | P39: 0 | Q39: 1
A40: Home Economics | B40: 4 | C40: 4 | D40: 4 | E40: 3 | F40: 4 | G40: 0 | H40: 1 | I40: 4 | J40: 1 | K40: 4 | L40: 2 | M40: 3 | N40: 2 | O40: 3 | P40: 1 | Q40: 4
A42: Geography | B42: 32 | C42: 32 | D42: 33 | E42: 22 | F42: 36 | G42: 35 | H42: 1 | I42: 32 | J42: 1 | K42: 31 | L42: 5 | M42: 39 | N42: 6 | O42: 37 | P42: 2 | Q42: 32
A43: History | B43: 38 | C43: 37 | D43: 39 | E43: 30 | F43: 42 | G43: 40 | H43: 1 | I43: 37 | J43: 1 | K43: 37 | L43: 5 | M43: 42 | N43: 5 | O43: 40 | P43: 2 | Q43: 37
A44: Humanities | B44: 2 | C44: 2 | D44: 2 | E44: 3 | F44: 2 | G44: 2 | H44: 0 | I44: 2 | J44: 1 | K44: 2 | L44: x | M44: 0 | N44: 1 | O44: 0 | P44: 1 | Q44: 2
A45: Economics | B45: 1 | C45: 0 | D45: 1 | E45: 1 | F45: 1 | G45: 0 | H45: x | I45: 1 | J45: x | K45: 1 | L45: 0 | M45: 1 | N45: x | O45: 1 | P45: x | Q45: 1
A46: Social Studies | B46: 7 | C46: 7 | D46: 7 | E46: 9 | F46: 7 | G46: 1 | H46: 0 | I46: 7 | J46: 1 | K46: 7 | L46: 0 | M46: 2 | N46: 1 | O46: 2 | P46: 0 | Q46: 7
A48: Any Modern Language | B48: 48 | C48: 46 | D48: 50 | E48: 33 | F48: 55 | G48: 44 | H48: 0 | I48: 47 | J48: 2 | K48: 46 | L48: 3 | M48: 63 | N48: 1 | O48: 60 | P48: 1 | Q48: 48
...

Sheet Table 10b
A1: Table 10b: GCSE entries in selected subjects by pupils at the end of key stage 4 by admission basis (percentage)
A2: Year: 2012/131 (Revised)
A3: Coverage: England
E4: As a percentage of pupils at the end of key stage 4 in each school type2
B5: Comprehensive schools | C5: Selective schools | D5: Modern schools | E5: All state-funded mainstream schools3
A7: Any Subject | B7: 100 | C7: 100 | D7: 100 | E7: 100
A9: English & Mathematics | B9: 92 | C9: 86 | D9: 88 | E9: 92
A10: Mathematics & Science | B10: 79 | C10: 83 | D10: 77 | E10: 79
A11: English, Mathematics & Science | B11: 75 | C11: 77 | D11: 68 | E11: 75
A13: English4 | B13: 93 | C13: 90 | D13: 88 | E13: 93
A14: English | B14: 25 | C14: 1 | D14: 34 | E14: 25
A15: English Language5 | B15: 68 | C15: 89 | D15: 54 | E15: 68
A17: Mathematics | B17: 99 | C17: 95 | D17: 99 | E17: 98
A19: Any Science | B19: 80 | C19: 88 | D19: 77 | E19: 80
A20: Core Science | B20: 55 | C20: 21 | D20: 60 | E20: 54
A21: Additional Science | B21: 43 | C21: 20 | D21: 46 | E21: 42
A22: Additional Applied Science | B22: 2 | C22: 0 | D22: 3 | E22: 2
... A63: Other Classical Studies | B63: 0 | C63: 0 | D63: 0 | E63: 0
A65: Applied Art and Design | B65: 0 | C65: x | D65: 0 | E65: 0
A66: Applied Physical Education | B66: . | C66: . | D66: . | E66: .
A67: Art and Design | B67: 25 | C67: 26 | D67: 27 | E67: 25
A68: Communication Studies | B68: 1 | C68: 1 | D68: 3 | E68: 2
A69: Construction | B69: 0 | C69: 0 | D69: 0 | E69: 0
A70: Drama | B70: 11 | C70: 14 | D70: 10 | E70: 11
A71: English Literature | B71: 71 | C71: 89 | D71: 60 | E71: 71
A72: English Studies | B72: 0 | C72: 0 | D72: 0 | E72: 0
A73: General Studies | B73: 1 | C73: 1 | D73: 0 | E73: 1
A74: Health and Social Care | B74: 1 | C74: 1 | D74: 1 | E74: 1
A75: Hospitality and Catering | B75: 0 | C75: 0 | D75: 0 | E75: 0
A76: Leisure and Tourism | B76: 0 | C76: x | D76: 1 | E76: 0
A77: Manufacturing | B77: 0 | C77: 0 | D77: 0 | E77: 0
A78: Media/Film/TV | B78: 9 | C78: 3 | D78: 10 | E78: 9
A79: Media: Communication and Production | B79: . | C79: . | D79: . | E79: .
A80: Music | B80: 6 | C80: 12 | D80: 4 | E80: 6
A81: Performing Arts | B81: 1 | C81: 1 | D81: 1 | E81: 1
A82: Physical Education | B82: 17 | C82: 19 | D82: 14 | E82: 17
A83: Religious Studies | B83: 38 | C83: 46 | D83: 32 | E83: 38
A84: Statistics | B84: 7 | C84: 13 | D84: 12 | E84: 8
A85: Vocational Studies | B85: 6 | C85: 2 | D85: 7 | E85: 6
F87: Source: 2012/13 key stage 4 attainment data (Revised)
...

Sheet Table 11
A1: Table 11: GCSE results of pupils at the end of key stage 4 in schools, by subject and grade1
A2: Year: 2012/132 (Revised)
A3: Coverage: England
M4: Entries (thousands)
B5: Grades obtained | M5: Total
A6: Subjects | B6: A* | C6: A | D6: B | E6: C | F6: D | G6: E | H6: F | I6: G | J6: U3 | K6: X4 | M6: entries
A8: English5 | B8: 22.3 | C8: 71.6 | D8: 127.7 | E8: 167.7 | F8: 91.3 | G8: 42.9 | H8: 18.1 | I8: 5.9 | J8: 2.8 | K8: 0.5 | M8: 550.8
A9: English | B9: 0.6 | C9: 2.9 | D9: 10.9 | E9: 40.9 | F9: 43.1 | G9: 28.2 | H9: 13.3 | I9: 4.4 | J9: 2.1 | K9: 0.3 | M9: 146.6
A10: English Language6 | B10: 21.7 | C10: 68.7 | D10: 116.7 | E10: 126.9 | F10: 48.2 | G10: 14.6 | H10: 4.9 | I10: 1.5 | J10: 0.7 | K10: 0.2 | M10: 404.2
A11: Mathematics | B11: 41.7 | C11: 77 | D11: 119.8 | E11: 200.2 | F11: 62.6 | G11: 38.6 | H11: 31.1 | I11: 21.1 | J11: 7.5 | K11: 3.5 | M11: 603.2
A13: Core Science | B13: 4 | C13: 21 | D13: 57.9 | E13: 110.6 | F13: 62.2 | G13: 35.6 | H13: 18.3 | I13: 7.6 | J13: 3.3 | K13: 1.5 | M13: 322
A14: Additional Science | B14: 6.2 | C14: 22.5 | D14: 50.9 | E14: 82.5 | F14: 50.3 | G14: 21.2 | H14: 9.3 | I14: 3.5 | J14: 1.7 | K14: 0.5 | M14: 248.5
A15: Additional Applied Science | B15: 0 | C15: 0.2 | D15: 0.9 | E15: 2.8 | F15: 3.5 | G15: 2.5 | H15: 1.2 | I15: 0.5 | J15: 0.3 | K15: 0.1 | M15: 11.8
A16: Physics | B16: 24.3 | C16: 38.4 | D16: 41.8 | E16: 32 | F16: 10.5 | G16: 1.8 | H16: 0.4 | I16: 0.1 | J16: 0 | K16: 0 | M16: 149.4
A17: Chemistry | B17: 25.9 | C17: 39.3 | D17: 40.8 | E17: 31.1 | F17: 10.9 | G17: 2.1 | H17: 0.5 | I17: 0.1 | J17: 0.1 | K17: 0 | M17: 150.8
A18: Biological Sciences | B18: 23.5 | C18: 41.5 | D18: 43.4 | E18: 31.2 | F18: 10 | G18: 1.9 | H18: 0.5 | I18: 0.2 | J18: 0.2 | K18: 0.1 | M18: 152.4
A19: Other Sciences | B19: 0.5 | C19: 0.9 | D19: 1.1 | E19: 1.2 | F19: 0.9 | G19: 0.6 | H19: 0.4 | I19: 0.2 | J19: 0.1 | K19: 0 | M19: 6
A21: D & T: Electronic Products | B21: 0.8 | C21: 1.2 | D21: 1.8 | E21: 1.7 | F21: 1.3 | G21: 0.8 | H21: 0.5 | I21: 0.3 | J21: 0.2 | K21: 0 | M21: 8.5
... A24: D & T: Resistant Materials | B24: 2.3 | C24: 5.7 | D24: 10.2 | E24: 12.5 | F24: 9.7 | G24: 6 | H24: 3.4 | I24: 1.7 | J24: 0.8 | K24: 0.1 | M24: 52.4
A25: D & T: Systems & Control | B25: 0.2 | C25: 0.5 | D25: 0.7 | E25: 0.8 | F25: 0.6 | G25: 0.3 | H25: 0.1 | I25: 0.1 | J25: 0.1 | K25: x | M25: 3.5
A26: D & T: Textiles Technology | B26: 2.8 | C26: 5.1 | D26: 6.6 | E26: 6.1 | F26: 3.6 | G26: 1.9 | H26: 1 | I26: 0.5 | J26: 0.2 | K26: 0.1 | M26: 27.8
A27: Other Design and Technology7 | B27: 1.6 | C27: 3.7 | D27: 6.6 | E27: 8.2 | F27: 6 | G27: 3.7 | H27: 2.2 | I27: 1.1 | J27: 0.6 | K27: 0.1 | M27: 33.8
A28: Applied Engineering | B28: 0 | C28: 0.1 | D28: 0.3 | E28: 0.5 | F28: 0.5 | G28: 0.4 | H28: 0.2 | I28: 0.1 | J28: 0 | K28: 0 | M28: 2.1
A29: Information Technology8 | B29: 4.2 | C29: 10.9 | D29: 14.2 | E29: 12.8 | F29: 6.7 | G29: 3.7 | H29: 2.5 | I29: 1.6 | J29: 0.9 | K29: 0.2 | M29: 57.7
A30: Business Studies | B30: 2.4 | C30: 9.9 | D30: 16.1 | E30: 15.3 | F30: 9.8 | G30: 5.5 | H30: 3.1 | I30: 1.6 | J30: 0.7 | K30: 0.1 | M30: 64.4
A31: Applied Business | B31: 0.1 | C31: 0.6 | D31: 1.1 | E31: 1.1 | F31: 0.8 | G31: 0.4 | H31: 0.3 | I31: 0.2 | J31: 0.2 | K31: 0 | M31: 4.7
A32: Home Economics | B32: 0.7 | C32: 2.8 | D32: 5.2 | E32: 6.3 | F32: 5.2 | G32: 3.2 | H32: 1.8 | I32: 0.7 | J32: 0.4 | K32: 0.1 | M32: 26.2
A34: Geography | B34: 19.9 | C34: 35.3 | D34: 40.8 | E34: 43.4 | F34: 29.7 | G34: 16.5 | H34: 8.8 | I34: 4.2 | J34: 1.6 | K34: 0.1 | M34: 200.2
A35: History | B35: 24.2 | C35: 43.8 | D35: 49.6 | E35: 45.1 | F35: 31.1 | G35: 18.8 | H35: 11.5 | I35: 6.6 | J35: 3.7 | K35: 0.2 | M35: 234.7
A36: Humanities | B36: 0.2 | C36: 0.8 | D36: 1.9 | E36: 2.7 | F36: 2.4 | G36: 1.9 | H36: 1.3 | I36: 0.8 | J36: 0.5 | K36: 0 | M36: 12.4
A37: Economics | B37: 0.3 | C37: 1 | D37: 1.2 | E37: 0.9 | F37: 0.4 | G37: 0.2 | H37: 0.1 | I37: 0.1 | J37: 0 | K37: 0 | M37: 4.3
A38: Social Studies | B38: 1.5 | C38: 6.1 | D38: 10.4 | E38: 10.5 | F38: 6.8 | G38: 4.1 | H38: 2.5 | I38: 1.4 | J38: 0.7 | K38: 0.1 | M38: 44.1
A40: Any Modern Language
A41: Arabic | B41: 0.7 | C41: 0.6 | D41: 0.4 | E41: 0.3 | F41: 0.2 | G41: 0.1 | H41: 0.1 | I41: 0.1 | J41: 0.1 | K41: 0 | M41: 2.6
A42: Chinese | B42: 1.5 | C42: 0.4 | D42: 0.3 | E42: 0.1 | F42: 0.1 | G42: 0 | H42: 0 | I42: x | J42: 0 | K42: 0 | M42: 2.3
A43: French | B43: 15.7 | C43: 23.5 | D43: 32.1 | E43: 42.2 | F43: 29.4 | G43: 11.9 | H43: 4.8 | I43: 1.6 | J43: 0.5 | K43: 0.2 | M43: 161.8
A44: German | B44: 5.4 | C44: 9 | D44: 14.1 | E44: 16.8 | F44: 9.7 | G44: 3.6 | H44: 1.3 | I44: 0.4 | J44: 0.1 | K44: 0 | M44: 60.3
A45: Italian | B45: 1.6 | C45: 0.8 | D45: 0.7 | E45: 0.6 | F45: 0.3 | G45: 0.1 | H45: 0 | I45: 0 | J45: 0 | K45: 0 | M45: 4.1
A46: Polish | B46: 0.9 | C46: 1.2 | D46: 0.5 | E46: 0.2 | F46: 0.1 | G46: 0 | H46: 0 | I46: 0 | J46: 0 | K46: 0 | M46: 2.9
A47: Spanish | B47: 10.4 | C47: 13.6 | D47: 16.1 | E47: 19.3 | F47: 13.2 | G47: 5.8 | H47: 2.5 | I47: 1.1 | J47: 0.5 | K47: 0.1 | M47: 82.7
...

Sheet Table 12
A1: Table 12: International GCSE, Cambridge International Certificate and Edexcel Level1/2 Certificate results of pupils at the end of key stage 4 in schools, by subject and grade1
A2: Year: 2012/132 (Revised)
A3: Coverage: England
M4: Number
B5: Grades obtained | M5: Total
A6: Subjects | B6: A* | C6: A | D6: B | E6: C | F6: D | G6: E | H6: F | I6: G | J6: U3 | K6: X4 | M6: entries
A8: Applied Business | B8: x | C8: x | D8: 12 | E8: 12 | F8: 15 | G8: 10 | H8: 4 | I8: x | J8: x | K8: x | M8: 65
A9: Art and Design | B9: x | C9: x | D9: 6 | E9: 15 | F9: x | G9: 11 | H9: 3 | I9: x | J9: 0 | K9: 5 | M9: 77
A10: Biological Sciences | B10: 7833 | C10: 3115 | D10: 1875 | E10: 993 | F10: 316 | G10: 151 | H10: 74 | I10: 44 | J10: 69 | K10: 26 | M10: 14496
A11: Business Studies | B11: 87 | C11: 109 | D11: 113 | E11: 91 | F11: 45 | G11: 21 | H11: 15 | I11: 8 | J11: x | K11: x | M11: 500
A12: Chemistry | B12: 6889 | C12: 3096 | D12: 2151 | E12: 1397 | F12: 564 | G12: 287 | H12: 119 | I12: 38 | J12: 29 | K12: 22 | M12: 14592
A13: Chinese | B13: 758 | C13: 61 | D13: 18 | E13: x | F13: x | G13: x | H13: 0 | I13: 0 | J13: x | K13: x | M13: 846
A14: English for speakers of other languages | B14: 38 | C14: 128 | D14: 226 | E14: 399 | F14: 182 | G14: 115 | H14: 108 | I14: 54 | J14: 97 | K14: 36 | M14: 1383
A15: English Language | B15: 3387 | C15: 5648 | D15: 7419 | E15: 14170 | F15: 6575 | G15: 2305 | H15: 576 | I15: 277 | J15: 345 | K15: 382 | M15: 41084
A16: English Literature | B16: 2819 | C16: 2856 | D16: 2781 | E16: 2186 | F16: 1580 | G16: 1789 | H16: 1928 | I16: 1742 | J16: 1132 | K16: 191 | M16: 19004
A17: French | B17: 2359 | C17: 719 | D17: 500 | E17: 363 | F17: 163 | G17: 56 | H17: 31 | I17: 10 | J17: x | K17: x | M17: 4209
A18: Geography | B18: 1635 | C18: 1254 | D18: 677 | E18: 287 | F18: 107 | G18: 50 | H18: 18 | I18: 11 | J18: 6 | K18: 7 | M18: 4052
A19: German | B19: 957 | C19: 524 | D19: 275 | E19: 103 | F19: 18 | G19: 7 | H19: x | I19: x | J19: 0 | K19: 5 | M19: 1892
A20: Hindi | B20: 0 | C20: 4 | D20: x | E20: 7 | F20: 5 | G20: x | H20: x | I20: x | J20: x | K20: 0 | M20: 26
A21: History | B21: 3020 | C21: 1477 | D21: 733 | E21: 304 | F21: 128 | G21: 66 | H21: 23 | I21: 6 | J21: 5 | K21: 17 | M21: 5779
A22: Information Technology5 | B22: 281 | C22: 550 | D22: 421 | E22: 260 | F22: 185 | G22: 115 | H22: 42 | I22: 16 | J22: x | K22: x | M22: 1895
A23: Mathematics | B23: 12025 | C23: 6598 | D23: 3821 | E23: 2105 | F23: 608 | G23: 321 | H23: 243 | I23: 210 | J23: 38 | K23: 22 | M23: 25991
A24: Music | B24: 231 | C24: 80 | D24: 30 | E24: 4 | F24: 0 | G24: 0 | H24: 0 | I24: 0 | J24: 0 | K24: 0 | M24: 345
A25: Other Modern Languages | B25: x | C25: x | D25: x | E25: x | F25: x | G25: x | H25: x | I25: x | J25: x | K25: x | M25: x
A26: Physics | B26: 8336 | C26: 3447 | D26: 1970 | E26: 1118 | F26: 418 | G26: 211 | H26: 101 | I26: 32 | J26: 10 | K26: 19 | M26: 15662
A27: Spanish | B27: 2150 | C27: 1097 | D27: 477 | E27: 181 | F27: 54 | G27: 25 | H27: 9 | I27: 6 | J27: x | K27: x | M27: 4005
A29: All subjects | B29: 52828 | C29: 30770 | D29: 23509 | E29: 23998 | F29: 10978 | G29: 5543 | H29: 3298 | I29: 2460 | J29: 1748 | K29: 772 | M29: 155904
M31: Source: 2012/13 key stage 4 attainment data (Revised)
A32: 1. Excludes science double awards.
A33: 2. Includes entries and achievements by these pupils in previous academic years where only the best grade is counted per pupil.
A34: 3. Grade U refers to pupils' results which are ungraded or unclassified.
A35: 4. Grade X refers to pupils who were absent or whose results are pending.
A36: 5. Also includes computer studies, information systems and any combined syllabus of which information technology is the major part.
A38: x Figure has been suppressed due to low numbers (1 or 2 pupils) or where secondary suppression has been applied.

Sheet Table 13
A1: Table 13: Results of GCSEs in Applied subjects of pupils at the end of key stage 4 in schools, by subject and grade
A2: Year: 2012/131 (Revised)
A3: Coverage: England
R4: Number of awards
B5: Grades obtained | T5: Total entries
A6: Subjects2 | B6: A*A* | C6: A*A | D6: AA | E6: AB | F6: BB | G6: BC | H6: CC | I6: CD | J6: DD | K6: DE | L6: EE | M6: EF | N6: FF | O6: FG | P6: GG | Q6: U3 | R6: X4
A8: Applied Art and Design | B8: . | C8: . | D8: . | E8: . | F8: . | G8: . | H8: . | I8: . | J8: . | K8: . | L8: . | M8: . | N8: . | O8: . | P8: . | Q8: . | R8: . | T8: .
A9: Applied Business | B9: 87 | C9: 165 | D9: 267 | E9: 353 | F9: 405 | G9: 424 | H9: 358 | I9: 291 | J9: 192 | K9: 121 | L9: 87 | M9: 76 | N9: 54 | O9: 28 | P9: 23 | Q9: 36 | R9: 4 | T9: 2971
A10: Applied Information and Communication Technology | B10: 0 | C10: x | D10: 0 | E10: 0 | F10: 0 | G10: 0 | H10: 0 | I10: x | J10: 0 | K10: 0 | L10: 0 | M10: 0 | N10: 0 | O10: 0 | P10: 0 | Q10: 0 | R10: 0 | T10: x
A11: Applied Science | B11: 0 | C11: 0 | D11: 6 | E11: x | F11: 30 | G11: 85 | H11: 145 | I11: 123 | J11: 80 | K11: 89 | L11: 68 | M11: 51 | N11: 34 | O11: 29 | P11: 14 | Q11: x | R11: x | T11: 786
A12: Engineering | B12: 16 | C12: 55 | D12: 101 | E12: 106 | F12: 141 | G12: 200 | H12: 181 | I12: 167 | J12: 159 | K12: 132 | L12: 96 | M12: 66 | N12: 59 | O12: 59 | P12: 31 | Q12: 40 | R12: 4 | T12: 1613
A13: Health and Social Care | B13: 51 | C13: 100 | D13: 200 | E13: 370 | F13: 492 | G13: 705 | H13: 672 | I13: 586 | J13: 422 | K13: 329 | L13: 252 | M13: 203 | N13: 149 | O13: 111 | P13: 71 | Q13: x | R13: x | T13: 4786
A14: Hospitality and Catering | B14: x | C14: 27 | D14: 62 | E14: 63 | F14: 123 | G14: 129 | H14: 117 | I14: 98 | J14: 76 | K14: 47 | L14: 35 | M14: 15 | N14: 13 | O14: 3 | P14: 0 | Q14: 3 | R14: 0 | T14: 816
A15: Leisure and Tourism | B15: x | C15: x | D15: 22 | E15: 40 | F15: 36 | G15: 45 | H15: 58 | I15: 55 | J15: 39 | K15: 23 | L15: 22 | M15: 19 | N15: 15 | O15: 12 | P15: 12 | Q15: 12 | R15: 27 | T15: 446
A16: Manufacturing | B16: 9 | C16: 27 | D16: 22 | E16: 52 | F16: 52 | G16: 73 | H16: 72 | I16: 77 | J16: 85 | K16: 55 | L16: 45 | M16: 29 | N16: 18 | O16: 29 | P16: 17 | Q16: 26 | R16: 0 | T16: 688
A17: Performing Arts | B17: 0 | C17: 0 | D17: 0 | E17: x | F17: 0 | G17: 0 | H17: 0 | I17: x | J17: 0 | K17: 0 | L17: 0 | M17: 0 | N17: 0 | O17: 0 | P17: 0 | Q17: 0 | R17: 0 | T17: x
A19: All Subjects | B19: 169 | C19: 383 | D19: 680 | E19: 1002 | F19: 1279 | G19: 1661 | H19: 1603 | I19: 1398 | J19: 1053 | K19: 796 | L19: 605 | M19: 459 | N19: 342 | O19: 271 | P19: 168 | Q19: 200 | R19: 40 | T19: 12109
T21: Source: 2012/13 key stage 4 attainment data (Revised)
A22: 1. Includes entries and achievements by these pupils in previous academic years where only the best grade is counted per pupil.
A23: 2. Double award vocational GCSEs are equivalent to 2 GCSEs.
A24: 3. Grade U refers to pupils' results which are ungraded or unclassified.
A25: 4. Grade X refers to pupils who were absent or whose results are pending.
A27: x Figure has been suppressed due to low numbers (1 or 2 pupils) or where secondary suppression has been applied.

Sheet Table 14
A1: Table 14: GCSE (Short Course) results of pupils at the end of key stage 4 in all schools, by subject and grade
A2: Year: 2012/131 (Revised)
A3: Coverage: England
L4: Number of awards
B5: Grades obtained | L5: Total entries
B6: A* | C6: A | D6: B | E6: C | F6: D | G6: E | H6: F | I6: G | J6: U2 | K6: X3
A8: Ancient History | B8: 14 | C8: 31 | D8: x | E8: 17 | F8: 15 | G8: 6 | H8: x | I8: 0 | J8: 0 | K8: 0 | L8: 114
A9: Art and Design | B9: 47 | C9: 93 | D9: 355 | E9: 625 | F9: 636 | G9: 566 | H9: 442 | I9: 158 | J9: 106 | K9: 136 | L9: 3164
A10: Business Studies | B10: 18 | C10: 76 | D10: 106 | E10: 144 | F10: 118 | G10: 111 | H10: 81 | I10: 62 | J10: 23 | K10: 14 | L10: 753
A11: Citizenship | B11: 1525 | C11: 5816 | D11: 10024 | E11: 11328 | F11: 9126 | G11: 5600 | H11: 3189 | I11: 1658 | J11: 1017 | K11: 229 | L11: 49512
A12: Classical Civilisation | B12: 22 | C12: 57 | D12: 94 | E12: 93 | F12: 97 | G12: 58 | H12: 31 | I12: x | J12: x | K12: x | L12: 484
A13: Classical Greek | B13: 21 | C13: 25 | D13: 10 | E13: 16 | F13: x | G13: 7 | H13: 3 | I13: x | J13: 0 | K13: x | L13: 100
A14: Design and Technology | B14: 51 | C14: 244 | D14: 686 | E14: 1011 | F14: 945 | G14: 792 | H14: 503 | I14: 267 | J14: 156 | K14: 66 | L14: 4721
A15: Economics | B15: 64 | C15: 160 | D15: 339 | E15: 378 | F15: 209 | G15: 129 | H15: 84 | I15: 72 | J15: 162 | K15: 24 | L15: 1621
A16: English Studies | B16: 0 | C16: 0 | D16: 0 | E16: 3 | F16: 26 | G16: 16 | H16: 7 | I16: 0 | J16: 0 | K16: 0 | L16: 52
A17: French | B17: 6 | C17: 21 | D17: 78 | E17: 342 | F17: 544 | G17: 549 | H17: 358 | I17: 215 | J17: 76 | K17: 24 | L17: 2213
A18: Geography | B18: 11 | C18: 52 | D18: 89 | E18: 133 | F18: 166 | G18: 151 | H18: 97 | I18: 81 | J18: 50 | K18: 24 | L18: 854
A19: German | B19: x | C19: x | D19: 32 | E19: 126 | F19: 168 | G19: 165 | H19: 130 | I19: 76 | J19: 45 | K19: 6 | L19: 765
A20: History | B20: 9 | C20: 39 | D20: 72 | E20: 105 | F20: 121 | G20: 120 | H20: 125 | I20: 100 | J20: 109 | K20: 20 | L20: 820
A21: Information Technology | B21: 581 | C21: 1987 | D21: 2736 | E21: 2078 | F21: 1250 | G21: 806 | H21: 579 | I21: 330 | J21: 267 | K21: 70 | L21: 10684
A22: Italian | B22: 10 | C22: 11 | D22: 10 | E22: x | F22: 15 | G22: x | H22: x | I22: 3 | J22: 0 | K22: 0 | L22: 70
A23: Latin | B23: 20 | C23: 23 | D23: 30 | E23: 23 | F23: 18 | G23: 16 | H23: x | I23: 0 | J23: x | K23: 0 | L23: 138
A24: Media/Film/TV | B24: x | C24: x | D24: x | E24: x | F24: x | G24: x | H24: x | I24: x | J24: x | K24: x | L24: x
A25: Other Modern Languages | B25: 160 | C25: 167 | D25: 169 | E25: 173 | F25: 129 | G25: 92 | H25: 58 | I25: 31 | J25: 39 | K25: 26 | L25: 1044
A26: Physical Education | B26: 405 | C26: 1054 | D26: 1968 | E26: 2973 | F26: 2798 | G26: 1911 | H26: 1046 | I26: 336 | J26: 134 | K26: 97 | L26: 12722
A27: Psychology | B27: 11 | C27: 65 | D27: 114 | E27: 87 | F27: 50 | G27: 43 | H27: 39 | I27: 21 | J27: 25 | K27: 27 | L27: 482
A28: Religious Education | B28: 8867 | C28: 16280 | D28: 25068 | E28: 28745 | F28: 23713 | G28: 19724 | H28: 14292 | I28: 10046 | J28: 8298 | K28: 2999 | L28: 158032
A29: Sociology | B29: 28 | C29: 45 | D29: 89 | E29: 164 | F29: 94 | G29: 62 | H29: 56 | I29: 41 | J29: 25 | K29: 52 | L29: 656
A30: Spanish | B30: 11 | C30: 15 | D30: 33 | E30: 130 | F30: 197 | G30: 162 | H30: 114 | I30: 62 | J30: 28 | K30: 17 | L30: 769
A32: All subjects | B32: 11887 | C32: 26272 | D32: 42129 | E32: 48705 | F32: 40448 | G32: 31095 | H32: 21247 | I32: 13575 | J32: 10578 | K32: 3835 | L32: 249771
L34: Source: 2012/13 key stage 4 attainment data (Revised)
A35: 1. Includes entries and achievements by these pupils in previous academic years where only the best grade is counted per pupil.
A36: 2. Grade U refers to pupils' results which are ungraded or unclassified.
A37: 3. Grade X refers to pupils who were absent or whose results are pending.
A39: x Figure has been suppressed due to low numbers (1 or 2 pupils) or where secondary suppression has been applied.

Sheet Table 15
A1: Table 15: Other Qualification results of pupils at the end of key stage 4 in all schools, by type of qualification1
A2: Year: 2012/132 (Revised)
A3: Coverage: England
G4: Number of awards
A5: Type of Qualification | C5: Entry Level3 | E5: Level 1 | G5: Level 2 | I5: Level 3
A7: Entry Level Qualifications | C7: 74532
A8: VRQ | E8: 110134 | G8: 127607
A9: Key Skills | E9: 6316 | G9: 47727
A10: NVQ | E10: 25 | G10: 65
A11: NVQ language units | E11: 4687 | G11: 1845
A12: Basic Skills | E12: 10467 | G12: 34688
A13: Functional Skills | C13: 14904 | E13: 63336 | G13: 105764
A14: BTEC Award1 | E14: 6643 | G14: 9930
A15: BTEC Certificate1 | E15: 7334 | G15: 415983
A16: BTEC Diploma1 | E16: 1972 | G16: 77629
A17: OCR National Award1 | E17: 1410 | G17: 214273
A18: OCR National Certificate1 | E18: 8 | G18: 18548
A19: OCR National Diploma1 | G19: x
A20: Free-standing Mathematics Qualification | E20: 586 | G20: 1663 | I20: 16984
A21: Asset Languages | C21: 32116 | E21: 44491 | G21: 5556 | I21: 695
A22: AS Level | I22: 12992
A23: Applied AS Level | I23: 104
A24: Applied AS Level Double Award | I24: 3
I26: Source: 2012/13 key stage 4 attainment data (Revised)
A27: 1. BTEC and OCR qualifications awarded as part of the Qualifications and Credit Framework (QCF) are included in their respective BTEC and OCR qualification categories.
A28: 2. Including achievements by these pupils in previous academic years.
A29: 3. Entry level qualifications are assessed below GCSE grade G.

Sheet Table 16 data
B1: 1 | C1: =B1+1 -> 2 | D1: =C1+1 -> 3 | E1: =D1+1 -> 4 | F1: =E1+1 -> 5 | G1: =F1+1 -> 6 | H1: =G1+1 -> 7 | I1: =H1+1 -> 8 | J1: =I1+1 -> 9 | ... AI1: =AH1+1 -> 34
A2: Region | B2: LA_name | C2: (No column name) | D2: M_PUP | E2: M_5AC | F2: M_5ACEM | G2: M_5AG | H2: M_5AGEM | I2: M_ANYPASS | J2: M_PTSCNEWE | K2: M_PTSTNEWE | L2: M_entbasicn | M2: M_L2BASICS | N2: (No column name) | O2: F_PUP | P2: F_5AC | Q2: F_5ACEM | R2: F_5AG | S2: F_5AGEM | T2: F_ANYPASS | U2: F_PTSCNEWE | V2: F_PTSTNEWE | W2: F_entbasicn | X2: F_L2BASICS | Y2: (No column name) | Z2: T_PUP | AA2: T_5AC | AB2: T_5ACEM | AC2: T_AG | AD2: T_5AGEM | AE2: T_ANYPASS | AF2: T_PTSCNEWE | AG2: T_PTSTNEWE | AH2: T_entbasicn | AI2: L2BASICS
B3: North East | D3: 14623 | E3: 85.5 | F3: 54.7 | G3: 94.3 | H3: 92.4 | I3: 99 | J3: 334.9 | K3: 471.9 | L3: 94.9 | M3: 55.1 | O3: 14171 | P3: 90.4 | Q3: 64.1 | R3: 96.7 | S3: 95.1 | T3: 99.4 | U3: 358.4 | V3: 516.2 | W3: 97.4 | X3: 64.4 | Z3: 28794 | AA3: 87.9 | AB3: 59.3 | AC3: 95.5 | AD3: 93.7 | AE3: 99.2 | AF3: 346.5 | AG3: 493.7 | AH3: 96.2 | AI3: 59.7
B4: County Durham | D4: 2785 | E4: 89.1 | F4: 57.7 | G4: 95.4 | H4: 94.1 | I4: 99.5 | J4: 343.8 | K4: 490.4 | L4: 95.6 | M4: 58 | O4: 2684 | P4: 93.7 | Q4: 68.6 | R4: 97.7 | S4: 96.6 | T4: 99.9 | U4: 369.8 | V4: 543.1 | W4: 98 | X4: 68.8 | Z4: 5469 | AA4: 91.4 | AB4: 63.1 | AC4: 96.6 | AD4: 95.4 | AE4: 99.7 | AF4: 356.5 | AG4: 516.3 | AH4: 96.8 | AI4: 63.3
B5: Darlington | D5: 600 | E5: 88 | F5: 59.8 | G5: 94.7 | H5: 93.5 | I5: 99.7 | J5: 343 | K5: 486.4 | L5: 96.2 | M5: 60 | O5: 558 | P5: 92.7 | Q5: 70.1 | R5: 96.8 | S5: 95.5 | T5: 99.6 | U5: 364.6 | V5: 516.1 | W5: 97.8 | X5: 70.3 | Z5: 1158 | AA5: 90.2 | AB5: 64.8 | AC5: 95.7 | AD5: 94.5 | AE5: 99.7 | AF5: 353.4 | AG5: 500.7 | AH5: 97 | AI5: 64.9
B6: Gateshead | D6: 1099 | E6: 87.9 | F6: 56.9 | G6: 93.4 | H6: 92.5 | I6: 98.9 | J6: 337.5 | K6: 476.2 | L6: 95.6 | M6: 57.1 | O6: 1076 | P6: 92.8 | Q6: 66.7 | R6: 96.3 | S6: 95.2 | T6: 99.4 | U6: 361.9 | V6: 521.2 | W6: 97.3 | X6: 67 | Z6: 2175 | AA6: 90.3 | AB6: 61.7 | AC6: 94.9 | AD6: 93.8 | AE6: 99.2 | AF6: 349.6 | AG6: 498.4 | AH6: 96.5 | AI6: 62
B7: Hartlepool | D7: 582 | E7: 74.4 | F7: 53.4 | G7: 93.5 | H7: 91.6 | I7: 99.7 | J7: 316.4 | K7: 412.7 | L7: 95.5 | M7: 54.5 | O7: 585 | P7: 86.5 | Q7: 64.4 | R7: 97.4 | S7: 96.9 | T7: 100 | U7: 352.5 | V7: 473.4 | W7: 98.3 | X7: 65.5 | Z7: 1167 | AA7: 80.5 | AB7: 59 | AC7: 95.5 | AD7: 94.3 | AE7: 99.8 | AF7: 334.5 | AG7: 443.1 | AH7: 96.9 | AI7: 60
B8: Middlesbrough | D8: 758 | E8: 83.1 | F8: 47.9 | G8: 94.3 | H8: 90.1 | I8: 98 | J8: 325.4 | K8: 450.5 | L8: 93.5 | M8: 48.2 | O8: 752 | P8: 84 | Q8: 52.7 | R8: 94.4 | S8: 90.7 | T8: 98.9 | U8: 339.6 | V8: 473.5 | W8: 95.9 | X8: 52.9 | Z8: 1510 | AA8: 83.6 | AB8: 50.3 | AC8: 94.4 | AD8: 90.4 | AE8: 98.5 | AF8: 332.5 | AG8: 462 | AH8: 94.7 | AI8: 50.5
B9: Newcastle upon Tyne | D9: 1319 | E9: 88.6 | F9: 52.8 | G9: 93.6 | H9: 91.4 | I9: 99.2 | J9: 331.6 | K9: 464.8 | L9: 94 | M9: 52.9 | O9: 1259 | P9: 92.1 | Q9: 62.1 | R9: 95.6 | S9: 93.8 | T9: 99.2 | U9: 353.2 | V9: 512.8 | W9: 96.7 | X9: 62.6 | Z9: 2578 | AA9: 90.3 | AB9: 57.3 | AC9: 94.5 | AD9: 92.6 | AE9: 99.2 | AF9: 342.1 | AG9: 488.3 | AH9: 95.3 | AI9: 57.6
B10: North Tyneside | D10: 1110 | E10: 87.7 | F10: 61.4 | G10: 95.4 | H10: 93.7 | I10: 99.4 | J10: 340 | K10: 480.1 | L10: 94.8 | M10: 61.6 | O10: 1041 | P10: 92.6 | Q10: 68.5 | R10: 97.3 | S10: 95.7 | T10: 99.2 | U10: 362.2 | V10: 524.5 | W10: 97.2 | X10: 68.8 | Z10: 2151 | AA10: 90.1 | AB10: 64.8 | AC10: 96.3 | AD10: 94.7 | AE10: 99.3 | AF10: 350.8 | AG10: 501.6 | AH10: 96 | AI10: 65.1
B11: Northumberland | D11: 1814 | E11: 80.4 | F11: 49.8 | G11: 92.6 | H11: 91.8 | I11: 98.1 | J11: 330.9 | K11: 459.2 | L11: 94.4 | M11: 50.1 | O11: 1774 | P11: 87.9 | Q11: 60.7 | R11: 95.9 | S11: 95 | T11: 99 | U11: 355.6 | V11: 498.7 | W11: 97.2 | X11: 60.9 | Z11: 3588 | AA11: 84.1 | AB11: 55.2 | AC11: 94.3 | AD11: 93.4 | AE11: 98.6 | AF11: 343.1 | AG11: 478.7 | AH11: 95.8 | AI11: 55.5
B12: Redcar and Cleveland | D12: 931 | E12: 79.9 | F12: 51.3 | G12: 92.7 | H12: 90.7 | I12: 97.9 | J12: 320.7 | K12: 444 | L12: 94.7 | M12: 51.7 | O12: 915 | P12: 86.7 | Q12: 59 | R12: 97 | S12: 96.1 | T12: 99.1 | U12: 352 | V12: 502.4 | W12: 98.3 | X12: 59.2 | Z12: 1846 | AA12: 83.3 | AB12: 55.1 | AC12: 94.9 | AD12: 93.3 | AE12: 98.5 | AF12: 336.2 | AG12: 472.9 | AH12: 96.5 | AI12: 55.4
B13: South Tyneside | D13: 886 | E13: 90.4 | F13: 54 | G13: 96.4 | H13: 94.1 | I13: 99.4 | J13: 348 | K13: 502 | L13: 96 | M13: 54.4 | O13: 850 | P13: 95.6 | Q13: 64.7 | R13: 98.7 | S13: 96.4 | T13: 99.4 | U13: 375.1 | V13: 552.8 | W13: 98 | X13: 64.7 | Z13: 1736 | AA13: 93 | AB13: 59.2 | AC13: 97.5 | AD13: 95.2 | AE13: 99.4 | AF13: 361.2 | AG13: 526.9 | AH13: 97 | AI13: 59.4
B14: Stockton-on-Tees | D14: 1130 | E14: 79 | F14: 54.1 | G14: 93.9 | H14: 91.5 | I14: 99.7 | J14: 330.7 | K14: 465.1 | L14: 93.2 | M14: 55 | O14: 1052 | P14: 83.7 | Q14: 61 | R14: 96 | S14: 93.2 | T14: 99.8 | U14: 345.7 | V14: 494.5 | W14: 96.5 | X14: 61.6 | Z14: 2182 | AA14: 81.3 | AB14: 57.4 | AC14: 94.9 | AD14: 92.3 | AE14: 99.8 | AF14: 337.9 | AG14: 479.3 | AH14: 94.8 | AI14: 58.2
... B166: England1 | D166: 323971 | E166: 78 | F166: 53.8 | G166: 92.9 | H166: 88.5 | I166: 99.3 | J166: 326.9 | K166: 435.9 | L166: 91.7 | M166: 54.7 | O166: 308705 | P166: 85.7 | Q166: 64.8 | R166: 95.8 | S166: 92.5 | T166: 100 | U166: 353.4 | V166: 483.1 | W166: 94.9 | X166: 65.4 | Z166: 632676 | AA166: 81.8 | AB166: 59.2 | AC166: 94.3 | AD166: 90.5 | AE166: 99.6 | AF166: 339.8 | AG166: 458.9 | AH166: 93.3 | AI166: 59.9
B167: England1,5 | D167: 323971 | E167: 78 | F167: 53.8 | G167: 92.9 | H167: 88.5 | I167: 99.3 | J167: 326.9 | K167: 435.9 | L167: 91.7 | M167: 54.7 | N167: 0 | O167: 308705 | P167: 85.7 | Q167: 64.8 | R167: 95.8 | S167: 92.5 | T167: 100 | U167: 353.4 | V167: 483.1 | W167: 94.9 | X167: 65.4 | Y167: 0 | Z167: 632676 | AA167: 81.8 | AB167: 59.2 | AC167: 94.3 | AD167: 90.5 | AE167: 99.6 | AF167: 339.8 | AG167: 458.9 | AH167: 93.3 | AI167: 59.9
B170: Boys
B171: Girls
B172: All
B174: Vlookup | C174: =VLOOKUP('Table 17'!I3,'Table 16 data'!B175:C176,2,0) -> 2 | D174: =IF(C174=1,3,12) -> 12
B175: 5 A*-C grades | C175: 1 | D175: 5 A*-C grades
B176: 5 A*-C grades inc E&M | C176: 2 | D176: 5+ A*-C grades including English and mathematics GCSEs

Sheet Table 16
A1: Table 16: GCSE and equivalent results of pupils at the end of key stage 4 by gender for each local authority1 and region
A2: Year: 2012/132 (Revised) | K2: Please select criteria
A3: Coverage: England | K3: Gender: | L3: Boys
C4: =IF(L3="Boys",0,IF(L3="Girls",11,22)) -> 0
C5: Number of end of key stage 4 pupils | D5: Percentage of pupils at the end of key stage 4 achieving at GCSE and equivalents: | I5: Average capped3 GCSE and equivalents point score per pupil | J5: Average GCSE and equivalents point score per pupil | K5: GCSE or iGCSE English and mathematics at A*-C
A6: Region/ Local Authority | B6: Region/ Local Authority number | D6: 5+A*-C grades | E6: 5+ A*-C including English and mathematics GCSEs | F6: 5+A*-G grades | G6: 5+ A*-G including English and mathematics GCSEs | H6: Any passes | K6: Per cent entered | L6: Per cent achieved
A8: North East | B8: E12000001 | C8: =VLOOKUP($A8,T16Percentage,$C$4+'Table 16 data'!D$1,0) -> 14623 | D8: =VLOOKUP($A8,T16Percentage,$C$4+'Table 16 data'!E$1,0) -> 85.5 | E8: =VLOOKUP($A8,T16Percentage,$C$4+'Table 16 data'!F$1,0) -> 54.7 | F8: =VLOOKUP($A8,T16Percentage,$C$4+'Table 16 data'!G$1,0) -> 94.3 | G8: =VLOOKUP($A8,T16Percentage,$C$4+'Table 16 data'!H$1,0) -> 92.4 | H8: =VLOOKUP($A8,T16Percentage,$C$4+'Table 16 data'!I$1,0) -> 99 | I8: =VLOOKUP($A8,T16Percentage,$C$4+'Table 16 data'!J$1,0) -> 334.9 | J8: =VLOOKUP($A8,T16Percentage,$C$4+'Table 16 data'!K$1,0) -> 471.9 | ... L8: =VLOOKUP($A8,T16Percentage,$C$4+'Table 16 data'!M$1,0) -> 55.1
A9: County Durham | B9: E06000047 | C9: =VLOOKUP($A9,T16Percentage,$C$4+'Table 16 data'!D$1,0) -> 2785 | D9: =VLOOKUP($A9,T16Percentage,$C$4+'Table 16 data'!E$1,0) -> 89.1 | E9: =VLOOKUP($A9,T16Percentage,$C$4+'Table 16 data'!F$1,0) -> 57.7 | F9: =VLOOKUP($A9,T16Percentage,$C$4+'Table 16 data'!G$1,0) -> 95.4 | G9: =VLOOKUP($A9,T16Percentage,$C$4+'Table 16 data'!H$1,0) -> 94.1 | H9: =VLOOKUP($A9,T16Percentage,$C$4+'Table 16 data'!I$1,0) -> 99.5 | I9: =VLOOKUP($A9,T16Percentage,$C$4+'Table 16 data'!J$1,0) -> 343.8 | J9: =VLOOKUP($A9,T16Percentage,$C$4+'Table 16 data'!K$1,0) -> 490.4 | ... L9: =VLOOKUP($A9,T16Percentage,$C$4+'Table 16 data'!M$1,0) -> 58
A10: Darlington | B10: E06000005 | C10: =VLOOKUP($A10,T16Percentage,$C$4+'Table 16 data'!D$1,0) -> 600 | D10: =VLOOKUP($A10,T16Percentage,$C$4+'Table 16 data'!E$1,0) -> 88 | E10: =VLOOKUP($A10,T16Percentage,$C$4+'Table 16 data'!F$1,0) -> 59.8 | F10: =VLOOKUP($A10,T16Percentage,$C$4+'Table 16 data'!G$1,0) -> 94.7 | G10: =VLOOKUP($A10,T16Percentage,$C$4+'Table 16 data'!H$1,0) -> 93.5 | H10: =VLOOKUP($A10,T16Percentage,$C$4+'Table 16 data'!I$1,0) -> 99.7 | I10: =VLOOKUP($A10,T16Percentage,$C$4+'Table 16 data'!J$1,0) -> 343 | J10: =VLOOKUP($A10,T16Percentage,$C$4+'Table 16 data'!K$1,0) -> 486.4 | ... L10: =VLOOKUP($A10,T16Percentage,$C$4+'Table 16 data'!M$1,0) -> 60
A11: Gateshead | B11: E08000020 | C11: =VLOOKUP($A11,T16Percentage,$C$4+'Table 16 data'!D$1,0) -> 1099 | D11: =VLOOKUP($A11,T16Percentage,$C$4+'Table 16 data'!E$1,0) -> 87.9 | E11: =VLOOKUP($A11,T16Percentage,$C$4+'Table 16 data'!F$1,0) -> 56.9 | F11: =VLOOKUP($A11,T16Percentage,$C$4+'Table 16 data'!G$1,0) -> 93.4 | G11: =VLOOKUP($A11,T16Percentage,$C$4+'Table 16 data'!H$1,0) -> 92.5 | H11: =VLOOKUP($A11,T16Percentage,$C$4+'Table 16 data'!I$1,0) -> 98.9 | I11: =VLOOKUP($A11,T16Percentage,$C$4+'Table 16 data'!J$1,0) -> 337.5 | J11: =VLOOKUP($A11,T16Percentage,$C$4+'Table 16 data'!K$1,0) -> 476.2 | ... L11: =VLOOKUP($A11,T16Percentage,$C$4+'Table 16 data'!M$1,0) -> 57.1
A12: Hartlepool | B12: E06000001 | C12: =VLOOKUP($A12,T16Percentage,$C$4+'Table 16 data'!D$1,0) -> 582 | D12: =VLOOKUP($A12,T16Percentage,$C$4+'Table 16 data'!E$1,0) -> 74.4 | E12: =VLOOKUP($A12,T16Percentage,$C$4+'Table 16 data'!F$1,0) -> 53.4 | F12: =VLOOKUP($A12,T16Percentage,$C$4+'Table 16 data'!G$1,0) -> 93.5 | G12: =VLOOKUP($A12,T16Percentage,$C$4+'Table 16 data'!H$1,0) -> 91.6 | H12: =VLOOKUP($A12,T16Percentage,$C$4+'Table 16 data'!I$1,0) -> 99.7 | I12: =VLOOKUP($A12,T16Percentage,$C$4+'Table 16 data'!J$1,0) -> 316.4 | J12: =VLOOKUP($A12,T16Percentage,$C$4+'Table 16 data'!K$1,0) -> 412.7 | ... L12: =VLOOKUP($A12,T16Percentage,$C$4+'Table 16 data'!M$1,0) -> 54.5
A13: Middlesbrough | B13: E06000002 | C13: =VLOOKUP($A13,T16Percentage,$C$4+'Table 16 data'!D$1,0) -> 758 | D13: =VLOOKUP($A13,T16Percentage,$C$4+'Table 16 data'!E$1,0) -> 83.1 | E13: =VLOOKUP($A13,T16Percentage,$C$4+'Table 16 data'!F$1,0) -> 47.9 | F13: =VLOOKUP($A13,T16Percentage,$C$4+'Table 16 data'!G$1,0) -> 94.3 | G13: =VLOOKUP($A13,T16Percentage,$C$4+'Table 16 data'!H$1,0) -> 90.1 | H13: =VLOOKUP($A13,T16Percentage,$C$4+'Table 16 data'!I$1,0) -> 98 | I13: =VLOOKUP($A13,T16Percentage,$C$4+'Table 16 data'!J$1,0) -> 325.4 | J13: =VLOOKUP($A13,T16Percentage,$C$4+'Table 16 data'!K$1,0) -> 450.5 | ... L13: =VLOOKUP($A13,T16Percentage,$C$4+'Table 16 data'!M$1,0) -> 48.2
A14: Newcastle upon Tyne | B14: E08000021 | C14: =VLOOKUP($A14,T16Percentage,$C$4+'Table 16 data'!D$1,0) -> 1319 | D14: =VLOOKUP($A14,T16Percentage,$C$4+'Table 16 data'!E$1,0) -> 88.6 | E14: =VLOOKUP($A14,T16Percentage,$C$4+'Table 16 data'!F$1,0) -> 52.8 | F14: =VLOOKUP($A14,T16Percentage,$C$4+'Table 16 data'!G$1,0) -> 93.6 | G14: =VLOOKUP($A14,T16Percentage,$C$4+'Table 16 data'!H$1,0) -> 91.4 | H14: =VLOOKUP($A14,T16Percentage,$C$4+'Table 16 data'!I$1,0) -> 99.2 | I14: =VLOOKUP($A14,T16Percentage,$C$4+'Table 16 data'!J$1,0) -> 331.6 | J14: =VLOOKUP($A14,T16Percentage,$C$4+'Table 16 data'!K$1,0) -> 464.8 | ... L14: =VLOOKUP($A14,T16Percentage,$C$4+'Table 16 data'!M$1,0) -> 52.9
A15: North Tyneside | B15: E08000022 | C15: =VLOOKUP($A15,T16Percentage,$C$4+'Table 16 data'!D$1,0) -> 1110 | D15: =VLOOKUP($A15,T16Percentage,$C$4+'Table 16 data'!E$1,0) -> 87.7 | E15: =VLOOKUP($A15,T16Percentage,$C$4+'Table 16 data'!F$1,0) -> 61.4 | F15: =VLOOKUP($A15,T16Percentage,$C$4+'Table 16 data'!G$1,0) -> 95.4 | G15: =VLOOKUP($A15,T16Percentage,$C$4+'Table 16 data'!H$1,0) -> 93.7 | H15: =VLOOKUP($A15,T16Percentage,$C$4+'Table 16 data'!I$1,0) -> 99.4 | I15: =VLOOKUP($A15,T16Percentage,$C$4+'Table 16 data'!J$1,0) -> 340 | J15: =VLOOKUP($A15,T16Percentage,$C$4+'Table 16 data'!K$1,0) -> 480.1 | ... L15: =VLOOKUP($A15,T16Percentage,$C$4+'Table 16 data'!M$1,0) -> 61.6
A16: Northumberland | B16: E06000048 | C16: =VLOOKUP($A16,T16Percentage,$C$4+'Table 16 data'!D$1,0) -> 1814 | D16: =VLOOKUP($A16,T16Percentage,$C$4+'Table 16 data'!E$1,0) -> 80.4 | E16: =VLOOKUP($A16,T16Percentage,$C$4+'Table 16 data'!F$1,0) -> 49.8 | F16: =VLOOKUP($A16,T16Percentage,$C$4+'Table 16 data'!G$1,0) -> 92.6 | G16: =VLOOKUP($A16,T16Percentage,$C$4+'Table 16 data'!H$1,0) -> 91.8 | H16: =VLOOKUP($A16,T16Percentage,$C$4+'Table 16 data'!I$1,0) -> 98.1 | I16: =VLOOKUP($A16,T16Percentage,$C$4+'Table 16 data'!J$1,0) -> 330.9 | J16: =VLOOKUP($A16,T16Percentage,$C$4+'Table 16 data'!K$1,0) -> 459.2 | ... L16: =VLOOKUP($A16,T16Percentage,$C$4+'Table 16 data'!M$1,0) -> 50.1
A17: Redcar and Cleveland | B17: E06000003 | C17: =VLOOKUP($A17,T16Percentage,$C$4+'Table 16 data'!D$1,0) -> 931 | D17: =VLOOKUP($A17,T16Percentage,$C$4+'Table 16 data'!E$1,0) -> 79.9 | E17: =VLOOKUP($A17,T16Percentage,$C$4+'Table 16 data'!F$1,0) -> 51.3 | F17: =VLOOKUP($A17,T16Percentage,$C$4+'Table 16 data'!G$1,0) -> 92.7 | G17: =VLOOKUP($A17,T16Percentage,$C$4+'Table 16 data'!H$1,0) -> 90.7 | H17: =VLOOKUP($A17,T16Percentage,$C$4+'Table 16 data'!I$1,0) -> 97.9 | I17: =VLOOKUP($A17,T16Percentage,$C$4+'Table 16 data'!J$1,0) -> 320.7 | J17: =VLOOKUP($A17,T16Percentage,$C$4+'Table 16 data'!K$1,0) -> 444 | ... L17: =VLOOKUP($A17,T16Percentage,$C$4+'Table 16 data'!M$1,0) -> 51.7
A18: South Tyneside | B18: E08000023 | C18: =VLOOKUP($A18,T16Percentage,$C$4+'Table 16 data'!D$1,0) -> 886 | D18: =VLOOKUP($A18,T16Percentage,$C$4+'Table 16 data'!E$1,0) -> 90.4 | E18: =VLOOKUP($A18,T16Percentage,$C$4+'Table 16 data'!F$1,0) -> 54 | F18: =VLOOKUP($A18,T16Percentage,$C$4+'Table 16 data'!G$1,0) -> 96.4 | G18: =VLOOKUP($A18,T16Percentage,$C$4+'Table 16 data'!H$1,0) -> 94.1 | H18: =VLOOKUP($A18,T16Percentage,$C$4+'Table 16 data'!I$1,0) -> 99.4 | I18: =VLOOKUP($A18,T16Percentage,$C$4+'Table 16 data'!J$1,0) -> 348 | J18: =VLOOKUP($A18,T16Percentage,$C$4+'Table 16 data'!K$1,0) -> 502 | ... L18: =VLOOKUP($A18,T16Percentage,$C$4+'Table 16 data'!M$1,0) -> 54.4
A19: Stockton-on-Tees | B19: E06000004 | C19: =VLOOKUP($A19,T16Percentage,$C$4+'Table 16 data'!D$1,0) -> 1130 | D19: =VLOOKUP($A19,T16Percentage,$C$4+'Table 16 data'!E$1,0) -> 79 | E19: =VLOOKUP($A19,T16Percentage,$C$4+'Table 16 data'!F$1,0) -> 54.1 | F19: =VLOOKUP($A19,T16Percentage,$C$4+'Table 16 data'!G$1,0) -> 93.9 | G19: =VLOOKUP($A19,T16Percentage,$C$4+'Table 16 data'!H$1,0) -> 91.5 | H19: =VLOOKUP($A19,T16Percentage,$C$4+'Table 16 data'!I$1,0) -> 99.7 | I19: =VLOOKUP($A19,T16Percentage,$C$4+'Table 16 data'!J$1,0) -> 330.7 | J19: =VLOOKUP($A19,T16Percentage,$C$4+'Table 16 data'!K$1,0) -> 465.1 | ... L19: =VLOOKUP($A19,T16Percentage,$C$4+'Table 16 data'!M$1,0) -> 55
... A106: Camden | B106: E09000007 | C106: =VLOOKUP($A106,T16Percentage,$C$4+'Table 16 data'!D$1,0) -> 627 | D106: =VLOOKUP($A106,T16Percentage,$C$4+'Table 16 data'!E$1,0) -> 69.1 | E106: =VLOOKUP($A106,T16Percentage,$C$4+'Table 16 data'!F$1,0) -> 49.6 | F106: =VLOOKUP($A106,T16Percentage,$C$4+'Table 16 data'!G$1,0) -> 92.7 | G106: =VLOOKUP($A106,T16Percentage,$C$4+'Table 16 data'!H$1,0) -> 91.7 | H106: =VLOOKUP($A106,T16Percentage,$C$4+'Table 16 data'!I$1,0) -> 97.9 | I106: =VLOOKUP($A106,T16Percentage,$C$4+'Table 16 data'!J$1,0) -> 316.2 | J106: =VLOOKUP($A106,T16Percentage,$C$4+'Table 16 data'!K$1,0) -> 408.9 | ... L106: =VLOOKUP($A106,T16Percentage,$C$4+'Table 16 data'!M$1,0) -> 51.7
A107: City of London | B107: E09000001 | C107: . | D107: . | E107: . | F107: . | G107: . | H107: . | I107: . | J107: . | K107: . | L107: .
A108: Hackney | B108: E09000012 | C108: =VLOOKUP($A108,T16Percentage,$C$4+'Table 16 data'!D$1,0) -> 682 | D108: =VLOOKUP($A108,T16Percentage,$C$4+'Table 16 data'!E$1,0) -> 77.6 | E108: =VLOOKUP($A108,T16Percentage,$C$4+'Table 16 data'!F$1,0) -> 58.7 | F108: =VLOOKUP($A108,T16Percentage,$C$4+'Table 16 data'!G$1,0) -> 94.3 | G108: =VLOOKUP($A108,T16Percentage,$C$4+'Table 16 data'!H$1,0) -> 91.5 | H108: =VLOOKUP($A108,T16Percentage,$C$4+'Table 16 data'!I$1,0) -> 98.8 | I108: =VLOOKUP($A108,T16Percentage,$C$4+'Table 16 data'!J$1,0) -> 325.3 | J108: =VLOOKUP($A108,T16Percentage,$C$4+'Table 16 data'!K$1,0) -> 404.5 | ... L108: =VLOOKUP($A108,T16Percentage,$C$4+'Table 16 data'!M$1,0) -> 60
